<?xml version='1.0'?>
<sdf version='1.6'>
  <model name='mouse'>
    <link name='base'>
      <pose>0 0 0.005 0 0 0</pose>
      <inertial>
        <pose frame=''>0.0095 0.0 0.019 0 0 0</pose>
        <mass>0.5</mass>
        <inertia>
          <ixx>2.8333e-4</ixx>
          <ixy>0</ixy>
          <ixz>0</ixz>
          <izz>6.6570e-4</izz>
          <iyz>0</iyz>
          <iyy>4.6770e-4</iyy>
        </inertia>
      </inertial>
      <visual name='whole_robot_visual'>
        <pose>0 0.032 0.015 1.5707 0 0</pose>
        <geometry>
          <mesh>
            <uri>model://mouse/body.stl</uri>
            <scale>0.001 0.001 0.001</scale>
          </mesh>
        </geometry>
        <material>
          <script>
            <name>Gazebo/Yellow</name>
            <uri>file://media/materials/scripts/gazebo.material</uri>
          </script>
        </material>
      </visual>
      <collision name='main_body_collision'>
        <pose frame=''>0.0095 0 0.019 0 0 0</pose>
        <geometry>
          <box>
            <size>0.101 0.076 0.032</size>
          </box>
        </geometry>
        <surface>
          <friction>
            <ode>
              <mu>0.01</mu>
              <mu2>0.01</mu2>
              <fdir1>0 0 0</fdir1>
              <slip1>0</slip1>
              <slip2>0</slip2>
            </ode>
          </friction>
          <contact>
            <ode>
              <soft_cfm>0</soft_cfm>
              <soft_erp>0.2</soft_erp>
              <kp>1e13</kp>
              <kd>1.0</kd>
              <max_vel>0.01</max_vel>
              <min_depth>0</min_depth>
            </ode>
          </contact>
        </surface>
      </collision>
      <collision name='front_runner_collision'>
        <pose frame=''>0.05 0 0.002 0 0 0</pose>
        <geometry>
          <box>
            <size>0.01 0.076 0.002</size>
          </box>
        </geometry>
        <surface>
          <friction>
            <ode>
              <mu>0.01</mu>
              <mu2>0.01</mu2>
              <fdir1>0 0 0</fdir1>
              <slip1>0</slip1>
              <slip2>0</slip2>
            </ode>
          </friction>
          <contact>
            <ode>
              <soft_cfm>0</soft_cfm>
              <soft_erp>0.2</soft_erp>
              <kp>1e13</kp>
              <kd>1.0</kd>
              <max_vel>0.01</max_vel>
              <min_depth>0</min_depth>
            </ode>
          </contact>
        </surface>
      </collision>
      <sensor name="laser" type="ray">
        <pose>0.02 0.0 0.002 0 0 -1.57079</pose>
        <ray>
          <scan>
            <horizontal>
              <samples>3</samples>
              <resolution>1</resolution>
              <min_angle>0.52359877</min_angle>
              <max_angle>2.61799387</max_angle>
            </horizontal>
          </scan>
          <range>
            <min>0.01</min>
            <max>0.2</max>
            <resolution>0.005</resolution>
          </range>
        </ray>
        <plugin name="laser" filename="libRayPlugin.so" />
        <always_on>1</always_on>
        <update_rate>10</update_rate>
        <visualize>true</visualize>
      </sensor>
    </link>
    <link name='right_wheel'>
      <pose frame=''>0.0 0.0313 0.02 0 1.57079 1.57079</pose>
      <inertial>
        <mass>0.01</mass>
        <inertia>
          <ixx>6.96908333e-07</ixx>
          <ixy>0</ixy>
          <ixz>0</ixz>
          <iyy>6.96908333e-07</iyy>
          <iyz>0</iyz>
          <izz>1.125e-06</izz>
        </inertia>
        <pose frame=''>0 0 0 0 0 0</pose>
      </inertial>
      <self_collide>0</self_collide>
      <kinematic>0</kinematic>
      <gravity>1</gravity>
      <visual name='visual'>
        <pose frame=''>0 0 0 0 0 0</pose>
        <geometry>
          <cylinder>
            <radius>0.015</radius>
            <length>0.0127</length>
          </cylinder>
        </geometry>
        <material>
          <script>
            <name>Gazebo/DarkGray</name>
            <uri>file://media/materials/scripts/gazebo.material</uri>
          </script>
        </material>
      </visual>
      <collision name='collision'>
        <pose frame=''>0 0 0 0 0 0</pose>
        <geometry>
          <cylinder>
            <radius>0.015</radius>
            <length>0.0127</length>
          </cylinder>
        </geometry>
        <surface>
          <friction>
            <ode>
              <mu>10</mu>
              <mu2>10</mu2>
            </ode>
            <torsional>
              <coefficient>1</coefficient>
              <patch_radius>0</patch_radius>
              <surface_radius>0</surface_radius>
              <use_patch_radius>1</use_patch_radius>
              <ode>
                <slip>0</slip>
              </ode>
            </torsional>
          </friction>
          <bounce>
            <restitution_coefficient>0</restitution_coefficient>
            <threshold>1e+06</threshold>
          </bounce>
          <contact>
            <collide_without_contact>0</collide_without_contact>
            <collide_without_contact_bitmask>1</collide_without_contact_bitmask>
            <collide_bitmask>1</collide_bitmask>
            <ode>
              <soft_cfm>0</soft_cfm>
              <soft_erp>0.2</soft_erp>
              <kp>1000000.0</kp>
              <kd>100.0</kd>
              <max_vel>0.01</max_vel>
              <min_depth>0</min_depth>
            </ode>
          </contact>
        </surface>
      </collision>
    </link>
    <link name='left_wheel'>
      <pose frame=''>0.0 -0.0313 0.02 0 1.57079 1.57079</pose>
      <inertial>
        <mass>0.01</mass>
        <inertia>
          <ixx>6.96908333e-07</ixx>
          <ixy>0</ixy>
          <ixz>0</ixz>
          <iyy>6.96908333e-07</iyy>
          <iyz>0</iyz>
          <izz>1.125e-06</izz>
        </inertia>
      </inertial>
      <self_collide>0</self_collide>
      <kinematic>0</kinematic>
      <visual name='visual'>
        <pose frame=''>0 0 0 0 0 0</pose>
        <geometry>
          <cylinder>
            <radius>0.015</radius>
            <length>0.0127</length>
          </cylinder>
        </geometry>
        <material>
          <script>
            <name>Gazebo/DarkGray</name>
            <uri>file://media/materials/scripts/gazebo.material</uri>
          </script>
        </material>
      </visual>
      <collision name='collision'>
        <pose frame=''>0 0 0 0 0 0</pose>
        <geometry>
          <cylinder>
            <radius>0.015</radius>
            <length>0.0127</length>
          </cylinder>
        </geometry>
        <surface>
          <friction>
            <ode>
              <mu>10</mu>
              <mu2>10</mu2>
            </ode>
            <torsional>
              <coefficient>1</coefficient>
              <patch_radius>0</patch_radius>
              <surface_radius>0</surface_radius>
              <use_patch_radius>1</use_patch_radius>
              <ode>
                <slip>0</slip>
              </ode>
            </torsional>
          </friction>
          <bounce>
            <restitution_coefficient>0</restitution_coefficient>
            <threshold>1e+06</threshold>
          </bounce>
          <contact>
            <collide_without_contact>0</collide_without_contact>
            <collide_without_contact_bitmask>1</collide_without_contact_bitmask>
            <collide_bitmask>1</collide_bitmask>
            <ode>
              <soft_cfm>0</soft_cfm>
              <soft_erp>0.2</soft_erp>
              <kp>1000000.0</kp>
              <kd>100.0</kd>
              <max_vel>0.01</max_vel>
              <min_depth>0</min_depth>
            </ode>
          </contact>
        </surface>
      </collision>
    </link>
    <joint name='left_wheel_joint' type='revolute'>
      <parent>base</parent>
      <child>left_wheel</child>
      <pose frame=''>0 0 0 0 0 0</pose>
      <axis>
        <xyz>0 0 1</xyz>
        <limit>
          <effort>0.1</effort>
          <velocity>40</velocity>
        </limit>
        <dynamics>
          <damping>0.00001</damping>
          <friction>0</friction>
        </dynamics>
      </axis>
      <physics>
        <ode>
          <implicit_spring_damper>true</implicit_spring_damper>
          <limit>
            <cfm>0</cfm>
            <erp>0.2</erp>
          </limit>
          <suspension>
            <cfm>0</cfm>
            <erp>0.2</erp>
          </suspension>
        </ode>
      </physics>
    </joint>
    <joint name='right_wheel_joint' type='revolute'>
      <parent>base</parent>
      <child>right_wheel</child>
      <pose frame=''>0 0 0 0 0 0</pose>
      <axis>
        <xyz>0 0 1</xyz>
        <use_parent_model_frame>0</use_parent_model_frame>
        <limit>
          <effort>0.1</effort>
          <velocity>40</velocity>
        </limit>
        <dynamics>
          <damping>0.00001</damping>
          <friction>0</friction>
        </dynamics>
      </axis>
      <physics>
        <ode>
          <implicit_spring_damper>true</implicit_spring_damper>
          <limit>
            <cfm>0</cfm>
            <erp>0.2</erp>
          </limit>
          <suspension>
            <cfm>0</cfm>
            <erp>0.2</erp>
          </suspension>
        </ode>
      </physics>
    </joint>
    <plugin name="mouse_plugin" filename="libmouse_plugin.so">
      <left_wheel_joint>left_wheel_joint</left_wheel_joint>
      <right_wheel_joint>right_wheel_joint</right_wheel_joint>
      <body>base</body>
    </plugin>
  </model>
</sdf>
<!--
.75 newtons front slip
.50 newtons side slip
--!>
