<?xml version='1.0'?>
<sdf version='1.6'>
  <model name='mouse'>
    <link name='base'>
      <pose>0 0 0.005 0 0 0</pose>
      <inertial>
        <pose frame=''>0.0095 0.0 0.019 0 0 0</pose>
        <mass>0.5</mass>
        <inertia>
          <ixx>2.8333e-4</ixx>
          <ixy>0</ixy>
          <ixz>0</ixz>
          <izz>6.6570e-4</izz>
          <iyz>0</iyz>
          <iyy>4.6770e-4</iyy>
        </inertia>
      </inertial>
      <visual name='whole_robot_visual'>
        <pose>0 0.032 0.015 1.5707 0 0</pose>
        <geometry>
          <mesh>
            <uri>model://mouse/body.stl</uri>
            <scale>0.001 0.001 0.001</scale>
          </mesh>
        </geometry>
        <material>
          <script>
            <name>Gazebo/Yellow</name>
            <uri>file://media/materials/scripts/gazebo.material</uri>
          </script>
        </material>
      </visual>
      <collision name='main_body_collision'>
        <max_contacts>6</max_contacts>
        <pose>0 0.032 0.015 1.5707 0 0</pose>
        <geometry>
          <mesh>
            <uri>model://mouse/body.stl</uri>
            <scale>0.001 0.001 0.001</scale>
          </mesh>
        </geometry>
        <surface>
          <friction>
            <ode>
              <mu>0.01</mu>
              <mu2>0.01</mu2>
            </ode>
          </friction>
          <contact>
            <ode>
              <soft_cfm>1.7e-10</soft_cfm>
              <soft_erp>0.17</soft_erp>
              <kp>1e9</kp>
              <kd>5e10</kd>
              <max_vel>0.01</max_vel>
              <min_depth>0</min_depth>
            </ode>
          </contact>
        </surface>
      </collision>
      <sensor name="left_analog" type="ray">
        <pose>0.040 0.024 0.015 0 0 0</pose>
        <ray>
          <scan>
            <horizontal>
              <samples>10</samples>
              <resolution>0.10</resolution>
              <min_angle>1.3089</min_angle>
              <max_angle>1.3962</max_angle>
            </horizontal>
          </scan>
          <range>
            <min>0.02</min>
            <max>0.15</max>
            <resolution>0.015</resolution>
          </range>
        </ray>
        <plugin name="left_analog_ray" filename="libRayPlugin.so" />
        <always_on>1</always_on>
        <update_rate>20</update_rate>
        <visualize>true</visualize>
      </sensor>
      <sensor name="right_analog" type="ray">
        <pose>0.040 -0.024 0.015 0 0 0</pose>
        <ray>
          <scan>
            <horizontal>
              <samples>10</samples>
              <resolution>.10</resolution>
              <min_angle>-1.3089</min_angle>
              <max_angle>-1.3962</max_angle>
            </horizontal>
          </scan>
          <range>
            <min>0.02</min>
            <max>0.15</max>
            <resolution>0.015</resolution>
          </range>
        </ray>
        <plugin name="right_analog_ray" filename="libRayPlugin.so" />
        <always_on>1</always_on>
        <update_rate>20</update_rate>
        <visualize>true</visualize>
      </sensor>
      <sensor name="left_binary" type="ray">
        <pose>0.043 0.022 0.015 0 0 0</pose>
        <ray>
          <scan>
            <horizontal>
              <samples>10</samples>
              <resolution>0.10</resolution>
              <min_angle>0.61</min_angle>
              <max_angle>0.69</max_angle>
            </horizontal>
          </scan>
          <range>
            <min>0.02</min>
            <max>0.15</max>
            <resolution>0.015</resolution>
          </range>
        </ray>
        <plugin name="left_binary_ray" filename="libRayPlugin.so" />
        <always_on>1</always_on>
        <update_rate>20</update_rate>
        <visualize>true</visualize>
      </sensor>
      <sensor name="right_binary" type="ray">
        <pose>0.043 -0.022 0.015 0 0 0</pose>
        <ray>
          <scan>
            <horizontal>
              <samples>10</samples>
              <resolution>0.10</resolution>
              <min_angle>-0.61</min_angle>
              <max_angle>-0.69</max_angle>
            </horizontal>
          </scan>
          <range>
            <min>0.02</min>
            <max>0.15</max>
            <resolution>0.015</resolution>
          </range>
        </ray>
        <plugin name="right_binary_ray" filename="libRayPlugin.so" />
        <always_on>1</always_on>
        <update_rate>20</update_rate>
        <visualize>true</visualize>
      </sensor>
      <sensor name="front_binary" type="ray">
        <pose>0.045 0 0.015 0 0 0</pose>
        <ray>
          <scan>
            <horizontal>
              <samples>10</samples>
              <resolution>0.10</resolution>
              <min_angle>-0.04</min_angle>
              <max_angle>0.04</max_angle>
            </horizontal>
          </scan>
          <range>
            <min>0.02</min>
            <max>0.15</max>
            <resolution>0.015</resolution>
          </range>
        </ray>
        <plugin name="front_binary_ray" filename="libRayPlugin.so" />
        <always_on>1</always_on>
        <update_rate>20</update_rate>
        <visualize>true</visualize>
      </sensor>
    </link>
    <link name='right_wheel'>
      <pose frame=''>0.0 -0.0313 0.019 0 1.57079 1.57079</pose>
      <inertial>
        <mass>0.01</mass>
        <inertia>
          <ixx>6.96908333e-07</ixx>
          <ixy>0</ixy>
          <ixz>0</ixz>
          <iyy>6.96908333e-07</iyy>
          <iyz>0</iyz>
          <izz>1.125e-06</izz>
        </inertia>
        <pose frame=''>0 0 0 0 0 0</pose>
      </inertial>
      <visual name='right_wheel_visual'>
        <pose frame=''>0 0 0 0 0 0</pose>
        <geometry>
          <cylinder>
            <radius>0.015</radius>
            <length>0.0127</length>
          </cylinder>
        </geometry>
        <material>
          <script>
            <name>Gazebo/DarkGray</name>
            <uri>file://media/materials/scripts/gazebo.material</uri>
          </script>
        </material>
      </visual>
      <collision name='right_wheel_collision'>
        <pose frame=''>0 0 0 0 0 0</pose>
        <max_contacts>2</max_contacts>
        <geometry>
          <cylinder>
            <radius>0.015</radius>
            <length>0.0127</length>
          </cylinder>
        </geometry>
        <surface>
          <friction>
            <ode>
              <mu>0.16</mu>
              <mu2>0.24</mu2>
              <fdir1>0 0 1</fdir1>
              <slip1>0</slip1>
              <slip2>0</slip2> <!-- increases "drifting" -->
            </ode>
          </friction>
          <contact>
            <ode>
              <soft_cfm>1.7e-10</soft_cfm>
              <soft_erp>0.17</soft_erp>
              <kp>1e9</kp>
              <kd>5e10</kd>
              <max_vel>0.01</max_vel>
              <min_depth>0</min_depth>
            </ode>
          </contact>
        </surface>
      </collision>
    </link>
    <link name='left_wheel'>
      <pose frame=''>0.0 0.0313 0.019 0 1.57079 1.57079</pose>
      <inertial>
        <mass>0.01</mass>
        <inertia>
          <ixx>6.96908333e-07</ixx>
          <ixy>0</ixy>
          <ixz>0</ixz>
          <iyy>6.96908333e-07</iyy>
          <iyz>0</iyz>
          <izz>1.125e-06</izz>
        </inertia>
      </inertial>
      <visual name='left_wheel_visual'>
        <pose frame=''>0 0 0 0 0 0</pose>
        <geometry>
          <cylinder>
            <radius>0.015</radius>
            <length>0.0127</length>
          </cylinder>
        </geometry>
        <material>
          <script>
            <name>Gazebo/DarkGray</name>
            <uri>file://media/materials/scripts/gazebo.material</uri>
          </script>
        </material>
      </visual>
      <collision name='left_wheel_collision'>
        <max_contacts>2</max_contacts>
        <pose frame=''>0 0 0 0 0 0</pose>
        <geometry>
          <cylinder>
            <radius>0.015</radius>
            <length>0.0127</length>
          </cylinder>
        </geometry>
        <surface>
          <friction>
            <ode>
              <mu>0.16</mu>
              <mu2>0.24</mu2>
              <fdir1>0 0 1</fdir1>
              <slip1>0</slip1>
              <slip2>0</slip2>
            </ode>
          </friction>
          <contact>
            <ode>
              <soft_cfm>1.7e-10</soft_cfm>
              <soft_erp>0.17</soft_erp>
              <kp>1e9</kp>
              <kd>5e10</kd>
              <max_vel>0.01</max_vel>
              <min_depth>0</min_depth>
            </ode>
          </contact>
        </surface>
      </collision>
    </link>
    <joint name='left_wheel_joint' type='revolute'>
      <parent>base</parent>
      <child>left_wheel</child>
      <pose frame=''>0 0 0 0 0 0</pose>
      <axis>
        <xyz>0 0 1</xyz>
        <limit>
          <effort>0.016</effort> <!-- 16 kg-cm -->
          <velocity>41.88</velocity> <!-- ~400 rpm -->
        </limit>
        <dynamics>
          <friction>0.00020</friction>
        </dynamics>
      </axis>
      <physics>
        <ode>
          <implicit_spring_damper>true</implicit_spring_damper>
          <limit>
            <cfm>0.2</cfm>
            <erp>0.2</erp>
          </limit>
          <suspension>
            <cfm>0.2</cfm>
            <erp>0.2</erp>
          </suspension>
        </ode>
      </physics>
    </joint>
    <joint name='right_wheel_joint' type='revolute'>
      <parent>base</parent>
      <child>right_wheel</child>
      <pose frame=''>0 0 0 0 0 0</pose>
      <axis>
        <xyz>0 0 1</xyz>
        <use_parent_model_frame>0</use_parent_model_frame>
        <limit>
          <effort>0.016</effort> <!-- 16 kg-cm -->
          <velocity>41.88</velocity> <!-- ~400 rpm -->
        </limit>
        <dynamics>
          <friction>0.00020</friction> <!-- not sure how to calculate this, or what the units are -->
        </dynamics>
      </axis>
      <physics>
        <ode>
          <implicit_spring_damper>true</implicit_spring_damper>
          <limit>
            <cfm>0</cfm>
            <erp>0.2</erp>
          </limit>
          <suspension>
            <cfm>0</cfm>
            <erp>0.2</erp>
          </suspension>
        </ode>
      </physics>
    </joint>
    <plugin name="mouse_plugin" filename="libmouse_plugin.so">
      <left_wheel_joint>left_wheel_joint</left_wheel_joint>
      <right_wheel_joint>right_wheel_joint</right_wheel_joint>
      <body>base</body>
    </plugin>
    <plugin name="link_plot_3d" filename="liblink_plot_3d_plugin.so">
      <minimum_distance>0.001</minimum_distance>
      <buffer_length>1000</buffer_length>
      <plot>
        <link>base</link>
        <pose>0 0 0.005 0 0 0</pose>
      </plot>
      <frequency>10000</frequency>
    </plugin>
  </model>
</sdf>
